
```typescript
import { Logger } from '@zs/sdk';

type AsyncFunc<T, Args extends any[] = any[]> = (...args: Args) => Promise<T>;

interface RetryOptions {
  retries?: number;
  delay?: number;
  cb?: (attempt: number, retries: number, isSuccess: boolean) => void;
}

const defaultRetriesCount = 10;
const defaultDelayTime = 1000;
/**
 * 封装一个带有重试机制的异步函数
 * @param {AsyncFunc<T, Args>} asyncFn - 需要执行的异步函数
 * @param {RetryOptions} [options={retries: 3, delay: 1000}] - 重试选项
 * @returns {(...args: Args) => Promise<T>} - 返回一个带有重试机制的异步函数
 */
export function withRetry<T, Args extends any[] = any[]>(
  asyncFn: AsyncFunc<T, Args>,
  options: RetryOptions = { retries: defaultRetriesCount, delay: defaultDelayTime },
): (...args: Args) => Promise<T> {
  const { retries = defaultRetriesCount, delay = defaultDelayTime, cb } = options;

  return async function (...args: Args): Promise<T> {
    for (let attempt = 0; attempt < retries!; attempt++) {
      try {
        cb && cb(attempt, retries!, false);
        const res = await asyncFn(...args);
        cb && cb(attempt, retries!, true);
        return res;
      } catch (error: any) {
        if (attempt === retries! - 1) {
          Logger.info('withRetry', `重试${retries}次，最终还是失败了：${error.message}`);
          // attemps传retries，说明重试一直失败
          cb && cb(retries, retries!, false);
          throw new Error(`Failed after ${retries} attempts: ${error.message}`);
        }
        Logger.info('withRetry', `重试${attempt + 1}次：${error.message}`);

        await new Promise((resolve) => setTimeout(resolve, delay));
      }
    }
    // 这里的代码实际上是不可达的，因为上面的循环要么成功返回，要么抛出错误
    throw new Error('Unreachable code'); // 这行只是为了类型安全而保留
  };
}

// async function fetchData(url: string, count: number): Promise<string> {
//   const response = await fetch(url);
//   if (!response.ok) {
//     throw new Error(`HTTP error! status: ${response.status}`);
//   }
//   return response.text();
// }

// const fetchDataWithRetry = withRetry(fetchData);

// fetchDataWithRetry('https://api.example.com/data', 123)
//   .then((data) => {
//     console.log('Data fetched successfully:', data);
//   })
//   .catch((error) => {
//     console.error('Error fetching data:', error);
//   });

```
